<?xml version="1.0"?>
<!--
  Gazebo ROS state plugin demo
  Try for example to get a model's state w.r.t. the world:
      ros2 service call /demo/get_entity_state 'gazebo_msgs/GetEntityState' '{name: "boxes"}'
  Or a link's state w.r.t. the world:
      ros2 service call /demo/get_entity_state 'gazebo_msgs/GetEntityState' '{name: "boxes::bottom", reference_frame: "world"}'
  Or a light's state w.r.t. another entity:
      ros2 service call /demo/get_entity_state 'gazebo_msgs/GetEntityState' '{name: "sun", reference_frame: "ground_plane"}'
  > When setting state, note that the changes for static entities may not be visible on gzclient due to https://bitbucket.org/osrf/gazebo/issues/2560
  Try teleporting a model:
      ros2 service call /demo/set_entity_state 'gazebo_msgs/SetEntityState' '{state: {name: "boxes", pose: {position: {y: 2}}}}'
  Or rotating a light:
      ros2 service call /demo/set_entity_state 'gazebo_msgs/SetEntityState' '{state: {name: "sun", pose: {position: {z: 10}, orientation: {x: 0.1, y: 0.2, z: 0.3, w: 0.5}}}}'
  Try teleporting a model:
      ros2 service call /demo/set_entity_state 'gazebo_msgs/SetEntityState' '{state: {name: "boxes::top", reference_frame: "boxes::top", twist: {angular: {x: 2}}}}'
  Try listening to model states:
      ros2 topic echo /demo/model_states_demo
  Try listening to link states:
      ros2 topic echo /demo/link_states_demo
-->
<sdf version="1.6">
  <world name="default">
    <plugin name="gazebo_ros_state" filename="libgazebo_ros_state.so">
      <ros>
        <namespace>/demo</namespace>
        <argument>model_states:=model_states_demo</argument>
        <argument>link_states:=link_states_demo</argument>
      </ros>

      <update_rate>1.0</update_rate>
    </plugin>

    <include>
      <uri>model://ground_plane</uri>
    </include>
    <include>
      <uri>model://sun</uri>
    </include>

    <!-- Edit world gravity here -->
    <gravity>0.0 0.0 -9.81</gravity>

    <!-- Pendulum object -->
    <model name='pendulum_0' canonical_link='string'>
      <pose relative_to='world'>0.0 0.0 1.0 0.0 0.0 0.0</pose>

      <link name='string'>
        <pose relative_to='__model__'>0.0 0.0 -0.25 0.0 0.0 0.0</pose>

        <inertial>
          <mass>0.1</mass>
          <inertia>
            <ixx>0.002084</ixx>
            <ixy>0</ixy>
            <ixz>0</ixz>
            <iyy>0.002084</iyy>
            <iyz>0</iyz>
            <izz>0.000001</izz>
          </inertia>
        </inertial>

        <visual name='visual'>
          <geometry>
            <cylinder>
              <radius>0.005</radius>
              <length>0.5</length>
            </cylinder>
          </geometry>
          <material>
            <ambient>0.5 0.5 0.5 1</ambient>
            <diffuse>0.5 0.5 0.5 1</diffuse>
            <specular>0.5 0.5 0.5 1</specular>
          </material>
        </visual>

        <collision name='collision'>
          <geometry>
            <cylinder>
              <radius>0.005</radius>
              <length>0.5</length>
            </cylinder>
          </geometry>
        </collision>

      </link>

      <link name='weight'>
        <pose relative_to='string'>0.0 0.0 -0.25 0.0 0.0 0.0</pose>

        <inertial>
          <mass>1.0</mass>
          <inertia>
            <ixx>0.001000</ixx>
            <ixy>0</ixy>
            <ixz>0</ixz>
            <iyy>0.001000</iyy>
            <iyz>0</iyz>
            <izz>0.001000</izz>
          </inertia>
        </inertial>

        <visual name='visual'>
          <geometry>
            <sphere>
              <radius>0.05</radius>
            </sphere>
          </geometry>
          <material>
            <ambient>0.5 0.5 0.5 1</ambient>
            <diffuse>0.5 0.5 0.6 1</diffuse>
            <specular>0.5 0.5 1.0 1</specular>
          </material>
        </visual>

        <collision name='collision'>
          <geometry>
            <sphere>
              <radius>0.05</radius>
            </sphere>
          </geometry>
        </collision>

      </link>

      <joint name='world_string' type='revolute'>
        <parent>world</parent>
        <child>string</child>
        <pose>0.0 0.0 0.25 0.0 0.0 0.0</pose>
        <axis>
          <xyz>0 1 0</xyz>
        </axis>
      </joint>
      
      <joint name='string_weight' type='fixed'>
        <parent>string</parent>
        <child>weight</child>
        <pose>0.0 0.0 0.0 0.0 0.0 0.0</pose>
      </joint>

    </model>

  </world>
</sdf>
